[master c264ffd] push
 2 files changed, 84 insertions(+)
 create mode 100644 nohup.out
To git@github.com:Semper-Invicta/AlbumMonitor.git
   7cd1996..c264ffd  master -> master
Branch master set up to track remote branch master from origin.
[master 6040c46] push
 2 files changed, 111 insertions(+)
To git@github.com:Semper-Invicta/AlbumMonitor.git
   c264ffd..6040c46  master -> master
Branch master set up to track remote branch master from origin.
[master af238bd] push
 2 files changed, 131 insertions(+)
To git@github.com:Semper-Invicta/AlbumMonitor.git
   6040c46..af238bd  master -> master
Branch master set up to track remote branch master from origin.
[master 02aaf05] push
 2 files changed, 131 insertions(+)
To git@github.com:Semper-Invicta/AlbumMonitor.git
   af238bd..02aaf05  master -> master
Branch master set up to track remote branch master from origin.
# On branch master
nothing to commit, working directory clean
Everything up-to-date
Branch master set up to track remote branch master from origin.
Traceback (most recent call last):
  File "./city/city.py", line 7, in <module>
    f = open('/workspaace/city/clog.txt','a')
FileNotFoundError: [Errno 2] No such file or directory: '/workspaace/city/clog.txt'
[master ae714de] push
 1 file changed, 8 insertions(+)
To git@github.com:Semper-Invicta/AlbumMonitor.git
   59bd35a..ae714de  master -> master
Branch master set up to track remote branch master from origin.
[master 92805be] push
 1 file changed, 5 insertions(+)
To git@github.com:Semper-Invicta/AlbumMonitor.git
   02ad0c4..92805be  master -> master
Branch master set up to track remote branch master from origin.
[master 8dcf6d0] push
 2 files changed, 131 insertions(+)
To git@github.com:Semper-Invicta/AlbumMonitor.git
   92805be..8dcf6d0  master -> master
Branch master set up to track remote branch master from origin.
[master ba445a9] push
 2 files changed, 131 insertions(+)
To git@github.com:Semper-Invicta/AlbumMonitor.git
   8dcf6d0..ba445a9  master -> master
Branch master set up to track remote branch master from origin.
[master d12d64c] push
 2 files changed, 89 insertions(+)
To git@github.com:Semper-Invicta/AlbumMonitor.git
   ba445a9..d12d64c  master -> master
Branch master set up to track remote branch master from origin.
[master 2d87ea3] push
 1 file changed, 5 insertions(+)
To git@github.com:Semper-Invicta/AlbumMonitor.git
   d12d64c..2d87ea3  master -> master
Branch master set up to track remote branch master from origin.
2018.11.18-22:04:32
26323
4648
20389
15494
789
4569
21317
13808
978
16563
17604
451
1073
883
1353
27096
1685
2351
1024
1035

2018.11.18-22:04:42
26323
4648
20390
15495
789
4570
21318
13808
978
16564
17605
451
1073
883
1353
27097
1685
2351
1024
1035

2018.11.18-22:04:53
26323
4648
20390
15495
789
4570
21318
13809
978
16564
17605
451
1073
883
1353
27098
1685
2351
1024
1035

2018.11.18-22:05:04
26324
4648
20391
15496
789
4570
21318
13812
978
16564
17605
451
1073
883
1353
27100
1685
2351
1024
1035

2018.11.18-22:05:14
26324
4648
20391
15497
789
4570
21318
13815
979
16564
17605
451
1073
883
1353
27101
1685
2351
1024
1035

2018.11.18-22:05:24
26324
4648
20391
15497
789
4570
21318
13815
979
16564
17605
451
1073
883
1353
27101
1685
2351
1024
1035

2018.11.18-22:05:35
26325
4648
20394
15500
789
4571
21319
13816
980
16564
17605
451
1073
883
1353
27103
1685
2351
1024
1035

2018.11.18-22:05:46
26325
4648
20394
15500
789
4571
21320
13822
980
16564
17605
451
1073
883
1353
27104
1685
2351
1024
1036

2018.11.18-22:05:57
26325
4648
20395
15500
789
4571
21320
13823
980
16565
17606
451
1073
883
1353
27105
1685
2351
1024
1036

2018.11.18-22:06:07
26325
4648
20395
15501
789
4571
21320
13827
980
16565
17606
451
1073
883
1353
27107
1685
2351
1024
1036

2018.11.18-22:06:18
26325
4648
20395
15501
789
4571
21320
13827
980
16565
17606
451
1073
883
1353
27107
1685
2351
1024
1036

2018.11.18-22:06:28
26327
4649
20396
15504
789
4571
21320
13831
980
16565
17607
451
1073
883
1353
27109
1686
2351
1024
1036

2018.11.18-22:06:39
26327
4649
20396
15504
789
4571
21320
13831
980
16565
17607
451
1073
883
1353
27109
1686
2351
1024
1036

2018.11.18-22:06:49
26328
4649
20396
15504
789
4572
21320
13831
980
16565
17607
451
1073
883
1353
27111
1686
2351
1024
1036

2018.11.18-22:07:00
26329
4649
20397
15508
789
4572
21321
13835
980
16565
17607
451
1073
883
1353
27114
1686
2351
1024
1036

2018.11.18-22:07:10
26329
4649
20398
15509
789
4572
21321
13836
980
16565
17607
451
1073
883
1353
27115
1687
2351
1024
1036

Traceback (most recent call last):
  File "/usr/local/python3/lib/python3.7/urllib/request.py", line 1317, in do_open
    encode_chunked=req.has_header('Transfer-encoding'))
  File "/usr/local/python3/lib/python3.7/http/client.py", line 1229, in request
    self._send_request(method, url, body, headers, encode_chunked)
  File "/usr/local/python3/lib/python3.7/http/client.py", line 1275, in _send_request
    self.endheaders(body, encode_chunked=encode_chunked)
  File "/usr/local/python3/lib/python3.7/http/client.py", line 1224, in endheaders
    self._send_output(message_body, encode_chunked=encode_chunked)
  File "/usr/local/python3/lib/python3.7/http/client.py", line 1016, in _send_output
    self.send(msg)
  File "/usr/local/python3/lib/python3.7/http/client.py", line 956, in send
    self.connect()
  File "/usr/local/python3/lib/python3.7/http/client.py", line 928, in connect
    (self.host,self.port), self.timeout, self.source_address)
  File "/usr/local/python3/lib/python3.7/socket.py", line 727, in create_connection
    raise err
  File "/usr/local/python3/lib/python3.7/socket.py", line 716, in create_connection
    sock.connect(sa)
TimeoutError: [Errno 110] Connection timed out

During handling of the above exception, another exception occurred:

Traceback (most recent call last):
  File "./city/city.py", line 9, in <module>
    req = urllib.request.urlopen(url)
  File "/usr/local/python3/lib/python3.7/urllib/request.py", line 222, in urlopen
    return opener.open(url, data, timeout)
  File "/usr/local/python3/lib/python3.7/urllib/request.py", line 525, in open
    response = self._open(req, data)
  File "/usr/local/python3/lib/python3.7/urllib/request.py", line 543, in _open
    '_open', req)
  File "/usr/local/python3/lib/python3.7/urllib/request.py", line 503, in _call_chain
    result = func(*args)
  File "/usr/local/python3/lib/python3.7/urllib/request.py", line 1345, in http_open
    return self.do_open(http.client.HTTPConnection, req)
  File "/usr/local/python3/lib/python3.7/urllib/request.py", line 1319, in do_open
    raise URLError(err)
urllib.error.URLError: <urlopen error [Errno 110] Connection timed out>
